Workbook

Sheet Sheet1
A1: MAWB NO. | B1: HAWB # | C1: Weight (Kgs) | D1: FLIGHT No. | E1: Shipper | F1: Consignee /IOR | G1: Incoterm | H1: CFS | I1: CHB | J1: Pre Alert Date | K1: Expected FLYING DATE | L1: ETD (Local airport time) | M1: ETD (Local airport time) | N1: ATD (Local airport time) | O1: ETA (Local airport time) | P1: Recovered | Q1: Number of pallets/Box | R1: Mode of delivery | S1: Carrier | T1: LTL vendor | U1: Delivery adress | V1: Estimated Price | W1: Achieved Price | X1: PRO # | Y1: Pickup Date | Z1: Estimate Delivery Date | AA1: Actual Delivery Date
A2: 074-55254286 | B2: X000661474 | C2: 975.1 | D2: DL-0049 | E2: Kalawati | F2: Beta Prep | H2: AMI | I2: RB | Q2: 49 Boxes/2 Pallets | R2: LTL | S2: - | T2: AMI | U2: 11767,NY US | V2: $858.41 | W2: $385.56 | X2: - | Y2: 46035 | Z2: 46035 | AA2: 46035
B3: X000662795 | C3: 1633 | D3: DL-0049 | E3: XLP | F3: Cooper Machine | G3: DAP | I3: CH Robinson | Q3: 128 Boxes/2 Pallets | R3: LTL | S3: ABF | T3: AMI | U3: 79765,TX US | V3: $800 | W3: $910.89 | X3: 218999075 | Y3: 46035 | Z3: 46042 | AA3: 46042
A5: 074-55254220 | B5: X000662781 | C5: 1100 | D5: AF-0006 | E5: Pioneer | F5: Amazon | H5: AMI | I5: WC | Q5: 100 Boxes/4 Pallets | R5: LTL | S5: TForce | T5: Echo Logistics | U5: 34986,FL US | V5: $980 | W5: $1126.69 | X5: 494837033 | Y5: 46035 | Z5: 46042 | AA5: 46043
B6: X000664578 | C6: 2186 | D6: AF-0006 | E6: Amit Kumar | F6: Amazon | I6: WC | Q6: 105 Boxes/5 Pallets | R6: UPS | S6: UPS | T6: - | U6: 46809,IN US | V6: $1,839.93 | W6: - | X6: - | Y6: 46037 | Z6: 46042 | AA6: 46048
A8: 125-17495914 | B8: X000669203 | C8: 1240 | D8: BA-256 | E8: Nikita Gupta | F8: ONETAP RETAIL | H8: AMI | I8: RB | J8: 46034 | K8: 46036 | L8: 46036 | M8: 46037.887 | P8: 46038 | Q8: 73 Boxes/2 Pallets | R8: FTL | S8: RBJ | T8: Veda Logistics | U8: 17225,PA US | V8: $1095 | W8: $223.78 | X8: 1072877135 | Y8: 46055 | Z8: 46055 | AA8: 46055
B9: X000669056 | C9: 67.24 | D9: BA-256 | E9: Relytek | F9: Amazon | I9: RB | J9: 46034 | K9: 46036 | L9: 46036.268 | M9: 46037.887 | P9: 46038 | Q9: 6 Boxes | R9: UPS | S9: UPS | T9: - | U9: 15672,PA US | V9: $110 | W9: $405 | X9: - | Y9: 46042 | Z9: 46044 | AA9: 46044
B10: X000665576 | C10: 248 | D10: BA-256 | E10: SINGAL INTERNATIONAL | F10: Amazon | I10: WC | J10: 46034 | K10: 46036 | L10: 46036.268 | M10: 46037.887 | P10: 46038 | Q10: 16 Boxes/1 Pallet | R10: LTL | S10: AF | T10: Amazon | U10: 17225,PA US | V10: $150 | W10: $70.19 | X10: 1073199125 | Y10: 46049 | Z10: 46056 | AA10: 46054
B11: X000667262 | C11: 81 | D11: BA-256 | E11: Royal Bee | F11: Amazon | I11: WC | J11: 46034 | K11: 46036 | L11: 46036.268 | M11: 46037.887 | P11: 46038 | Q11: 6 Boxes | R11: UPS | S11: UPS | T11: - | U11: 33032,FL US | V11: $71.24 | W11: - | X11: - | Y11: 46043 | Z11: 46049 | AA11: 46049
B12: X000667120 | C12: 646 | D12: BA-256 | E12: Pioneer | F12: Walmart | I12: WC | J12: 46034 | K12: 46036 | L12: 46036.268 | M12: 46037.887 | P12: 46038 | Q12: 56 Boxes/2 Pallets | R12: LTL | S12: TForce | T12: Echo Logistics | U12: 33897,FL US | V12: $850 | W12: $781.91 | X12: 494837232 | Y12: 46043 | Z12: 46051 | AA12: 46060
B13: X000668925 | C13: 214.5 | D13: BA-256 | E13: ANS | F13: Pratima Kumar | I13: WC | J13: 46034 | K13: 46036 | L13: 46036.268 | M13: 46037.887 | P13: 46038 | Q13: 3 Boxes/1 Pallets | R13: LTL | S13: TForce | T13: Echo Logistics | U13: 94583,CA US | V13: $205 | W13: $589.57 | X13: 494837243 | Y13: 46043 | Z13: 46050 | AA13: 46050
A15: 932-77370451 | B15: X000669596 | C15: 209.6 | D15: VS-301 | E15: JAMSTICKS INDIA PRIVATE LIMITED | F15: Power SCM | H15: AMI | I15: RB | J15: 46038 | K15: 46039 | L15: 46043.691 | M15: 46043.815 | P15: 46046 | Q15: 6 Boxes | R15: UPS | S15: UPS | T15: - | U15: 84065,UT US | V15: $183.05 | W15: - | X15: - | Y15: 46049 | Z15: 46056 | AA15: 46056
A16: 932-77370451 | B16: X000665536 | C16: 248 | D16: VS-301 | E16: SINGAL INTERNATIONAL | F16: Amazon | I16: WC | J16: 46038 | K16: 46039 | L16: 46043.691 | M16: 46043.815 | P16: 46046 | Q16: 16 Boxes | R16: LTL | S16: AF | T16: Amazon | U16: 17225,PA US | V16: $150 | W16: $70.19 | X16: 1073199125 | Y16: 46050 | Z16: 46056 | AA16: 46054
A17: 932-77370451 | B17: X000670495 | C17: 88 | D17: VS-301 | E17: TERUPATI BALAJI EXPO | F17: Bhupinder Singh | G17: DAP | I17: WC | J17: 46038 | K17: 46039 | L17: 46043.691 | M17: 46043.815 | P17: 46046 | Q17: 4 Boxes | R17: UPS | S17: UPS | T17: - | U17: 94928,CA US | V17: - | W17: - | X17: - | Y17: 46049 | Z17: 46056 | AA17: 46056
A18: 932-77370451 | B18: X000671917 | C18: 350 | D18: VS-301 | E18: XLP ENGINEERS PVT LTD | F18: S.B International | I18: WC | J18: 46038 | K18: 46039 | L18: 46043.691 | M18: 46043.815 | P18: 46046 | Q18: 28 Boxes/1 Pallet | R18: LTL | S18: Central Transport | T18: Trojan Horse | U18: 37211,TN US | V18: $266 | W18: $371 | X18: 95205472 | Y18: 46049 | Z18: 46051 | AA18: 46051
A19: 932-77370451 | B19: X000671678 | C19: 112 | D19: VS-301 | E19: AMZ MART | F19: Amazon | I19: WC | J19: 46038 | K19: 46039 | L19: 46043.691 | M19: 46043.815 | P19: 46046 | Q19: 8 Boxes/1 Pallet | R19: LTL | S19: AF | T19: Amazon | U19: 33032,FL US | V19: $408 | W19: $210.11 | X19: 1073158634 | Y19: 46050 | Z19: 46055 | AA19: 46054
A20: 932-77370451 | B20: X000672476 | C20: 422 | D20: VS-301 | E20: GEORGIAN CRAFTS | F20: Nature of Marble | G20: DAP | I20: RB | J20: 46038 | K20: 46039 | L20: 46043.691 | M20: 46043.815 | P20: 46046 | Q20: 15 Boxes/2 Pallets | R20: LTL | S20: Forward Air | T20: Trojan Horse | U20: 33445,FL US | V20: $411 | W20: $888 | X20: 95205577 | Y20: 46049 | Z20: 46051 | AA20: 46051
A22: 074-55254301 | B22: X000672818 | C22: 947.54 | D22: KL-872 | E22: RV INTERNATIONAL | F22: Amazon | H22: WC | I22: RB | J22: 46042 | K22: =IF(A22="","",XLOOKUP(A22,Sheet7!B:B,Sheet7!K:K)) -> #REF! | L22: =IF(A22="","",XLOOKUP(A22,Sheet7!B:B,Sheet7!R:T)) -> #REF! | P22: 46046 | Q22: 61 Boxes | R22: LTL | S22: TForce | T22: Trojan Horse | U22: 29330,SC US | V22: $608 | W22: $637 | X22: 284498970 | Y22: 46052 | Z22: 46056 | AA22: 46057
A23: 074-55254301 | B23: X000665449 | C23: 248 | D23: KL-872 | E23: SINGAL INTERNATIONAL | F23: Amazon | I23: WC | J23: 46042 | K23: =IF(A23="","",XLOOKUP(A23,Sheet7!B:B,Sheet7!K:K)) -> #REF! | L23: =IF(A23="","",XLOOKUP(A23,Sheet7!B:B,Sheet7!R:T)) -> #REF! | P23: 46046 | Q23: 16 Boxes | R23: LTL | S23: AF | T23: Amazon | U23: 17225,PA US | V23: $150 | W23: $117.78 | X23: 1073528703 | Y23: 46052 | Z23: 46059 | AA23: 46057
A24: 074-55254301 | B24: X000673403 | C24: 717 | D24: KL-872 | E24: PIONEER SERVICE PROVIDER | F24: Amazon | I24: WC | J24: 46042 | K24: =IF(A24="","",XLOOKUP(A24,Sheet7!B:B,Sheet7!K:K)) -> #REF! | L24: =IF(A24="","",XLOOKUP(A24,Sheet7!B:B,Sheet7!R:T)) -> #REF! | P24: 46046 | Q24: 66 Boxes | R24: LTL | S24: AF | T24: Amazon | U24: 33032,FL US | V24: $595 | W24: $500.50 | X24: 1073528810 | Y24: 46052 | Z24: 46056 | AA24: 46057
A25: 074-55254301 | B25: X000674307 | C25: 164.19 | D25: KL-872 | E25: AVADH CHIKAN CRAFT | F25: Amazon | I25: WC | J25: 46042 | K25: =IF(A25="","",XLOOKUP(A25,Sheet7!B:B,Sheet7!K:K)) -> #REF! | L25: =IF(A25="","",XLOOKUP(A25,Sheet7!B:B,Sheet7!R:T)) -> #REF! | P25: 46046 | Q25: 8 Boxes | R25: UPS | S25: UPS | T25: - | U25: 34986,FL US | V25: - | W25: - | X25: - | Y25: 46050 | Z25: 46056 | AA25: 46060
A26: 074-55254301 | B26: X000675302 | C26: 139.28 | D26: KL-872 | E26: FASHION POINT | F26: Lucria Consult LLC | G26: DAP | I26: WC | J26: 46042 | K26: =IF(A26="","",XLOOKUP(A26,Sheet7!B:B,Sheet7!K:K)) -> #REF! | L26: =IF(A26="","",XLOOKUP(A26,Sheet7!B:B,Sheet7!R:T)) -> #REF! | P26: 46046 | Q26: 9 Boxes | R26: UPS | S26: UPS | T26: - | U26: 06074,CT US | V26: - | W26: - | X26: - | Y26: 46050 | Z26: 46051 | AA26: 46051
A28: 125-17496043 | B28: X000676033 | C28: 1268.84 | D28: BA-117 | E28: P-Tal | F28: Karshini P-Tal | H28: 1C | I28: WC | J28: 46043 | K28: {=IF(A28="","",XLOOKUP(A28,Sheet7!B:B,Sheet7!K:K))} -> #REF! | L28: {=IF(A28="","",XLOOKUP(A28,Sheet7!B:B,Sheet7!R:T))} -> #REF! | P28: 46056 | Q28: 215 Boxes | R28: FTL | S28: RMC | T28: RMC Trucking | U28: 08817,NJ US | V28: $680 | W28: 1348.17 | X28: - | Y28: 46056 | Z28: 46056 | AA28: 46062
A30: 932-77370845 | B30: X000672056 | C30: 208 | E30: TURRITOPSIS | F30: Amazon | G30: DDP | H30: AMI | I30: WC | K30: =IF(A30="","",XLOOKUP(A30,Sheet7!B:B,Sheet7!K:K)) -> #REF! | L30: =IF(A30="","",XLOOKUP(A30,Sheet7!B:B,Sheet7!R:T)) -> #REF! | P30: 46064 | Q30: 26 Boxes | R30: UPS | S30: UPS | T30: - | U30: 33032,FL US | V30: $366 | Y30: 46065 | Z30: 46076 | AA30: 46076
A31: 932-77370845 | B31: X000678536 | C31: 99.9 | E31: Adret Retail Pvt Ltd | F31: Walmart | G31: DDP | I31: Regal | K31: =IF(A31="","",XLOOKUP(A31,Sheet7!B:B,Sheet7!K:K)) -> #REF! | L31: =IF(A31="","",XLOOKUP(A31,Sheet7!B:B,Sheet7!R:T)) -> #REF! | P31: 46064 | Q31: 12 Boxes | R31: UPS | S31: UPS | T31: - | U31: 30349,GA US | V31: $120 | Y31: 46065 | Z31: 46069 | AA31: 46069
A32: 932-77370845 | B32: X000678557 | C32: 147.92 | E32: AASHIRWAD GARMENTS | F32: Amazon | G32: DDP | I32: WC | K32: =IF(A32="","",XLOOKUP(A32,Sheet7!B:B,Sheet7!K:K)) -> #REF! | L32: =IF(A32="","",XLOOKUP(A32,Sheet7!B:B,Sheet7!R:T)) -> #REF! | P32: 46064 | Q32: 7 Boxes | R32: LTL | S32: AF | T32: Amazon | U32: 18031,PA US | V32: $135 | W32: $115 | Y32: 46065 | Z32: 46071 | AA32: 46067
A33: 932-77370845 | B33: X000678212 | C33: 315.92 | E33: MOKSHAMULTIVERSE PVT LTD | F33: Amazon | G33: DDP | I33: WC | K33: =IF(A33="","",XLOOKUP(A33,Sheet7!B:B,Sheet7!K:K)) -> #REF! | L33: =IF(A33="","",XLOOKUP(A33,Sheet7!B:B,Sheet7!R:T)) -> #REF! | P33: 46064 | Q33: 17 Boxes | R33: UPS | S33: UPS | T33: - | U33: 18447,PA US | V33: $137 | Y33: 46065 | Z33: 46069 | AA33: 46069
A34: 932-77370845 | B34: X000681029 | C34: 216.7 | E34: REDPLUM PRIVATE LIMITED | F34: Amazon | G34: DDP | I34: Regal | K34: =IF(A34="","",XLOOKUP(A34,Sheet7!B:B,Sheet7!K:K)) -> #REF! | L34: =IF(A34="","",XLOOKUP(A34,Sheet7!B:B,Sheet7!R:T)) -> #REF! | P34: 46064 | Q34: 17 Boxes | R34: LTL | S34: Estes | T34: Echo Logistics | U34: 15672,PA US | V34: $315 | X34: 1760861573 | Y34: 46066 | Z34: 46070 | AA34: 46073
A35: 932-77370845 | B35: X000682488 | C35: 73.7 | E35: ARNAV AGENCIES | F35: Amazon | G35: DDP | I35: Regal | K35: =IF(A35="","",XLOOKUP(A35,Sheet7!B:B,Sheet7!K:K)) -> #REF! | L35: =IF(A35="","",XLOOKUP(A35,Sheet7!B:B,Sheet7!R:T)) -> #REF! | P35: 46064 | Q35: 11 Boxes | R35: LTL | S35: AF | T35: Amazon Freight | U35: 18447,PA US | V35: $66 | X35: 1074301142 | Y35: 46065 | Z35: 46069 | AA35: 46073
A36: 932-77370845 | B36: X000682677 | C36: 105 | E36: Jai Govindam | F36: Amazon | G36: DDP | I36: WC | K36: =IF(A36="","",XLOOKUP(A36,Sheet7!B:B,Sheet7!K:K)) -> #REF! | L36: =IF(A36="","",XLOOKUP(A36,Sheet7!B:B,Sheet7!R:T)) -> #REF! | P36: 46064 | Q36: 5 Boxes | R36: UPS | S36: UPS | T36: - | U36: 21740,MD US | Y36: 46065 | Z36: 46066 | AA36: 46066
A37: 932-77370845 | B37: X000682816 | C37: 222 | E37: RV INTERNATIONAL | F37: Amazon | G37: DDP | I37: Regal | K37: =IF(A37="","",XLOOKUP(A37,Sheet7!B:B,Sheet7!K:K)) -> #REF! | L37: =IF(A37="","",XLOOKUP(A37,Sheet7!B:B,Sheet7!R:T)) -> #REF! | P37: 46064 | Q37: 15 Boxes | R37: UPS | S37: UPS | T37: - | U37: 29330,SC US | V37: $176 | Y37: 46065 | Z37: 46069 | AA37: 46069
A38: 932-77370845 | B38: X000682746 | C38: 133 | E38: Grownhome arts | F38: Amazon | G38: DDP | I38: WC | K38: =IF(A38="","",XLOOKUP(A38,Sheet7!B:B,Sheet7!K:K)) -> #REF! | L38: =IF(A38="","",XLOOKUP(A38,Sheet7!B:B,Sheet7!R:T)) -> #REF! | P38: 46064 | Q38: 7 Boxes | R38: UPS | S38: UPS | T38: - | U38: 33032,FL US | V38: $141 | Y38: 46065 | Z38: 46076 | AA38: 46076
A40: 125 -17478952 | B40: X000687343 | C40: 745 | E40: Pioneer | F40: Amazon | G40: DDP | H40: AMI | I40: WC | K40: =IF(A40="","",XLOOKUP(A40,Sheet7!B:B,Sheet7!K:K)) -> #REF! | L40: =IF(A40="","",XLOOKUP(A40,Sheet7!B:B,Sheet7!R:T)) -> #REF! | P40: 46071 | Q40: 63 Boxes | R40: LTL | S40: AF | T40: Amazon | U40: 33032 ,FL US | V40: $437 | W40: $369.35 | X40: 1074711100 | Y40: 46072 | Z40: 46076
A41: 125 -17478952 | B41: X000685516 | C41: 37.15 | E41: Blue Tea | F41: Walmart | G41: DDP | I41: Regal | K41: =IF(A41="","",XLOOKUP(A41,Sheet7!B:B,Sheet7!K:K)) -> #REF! | L41: =IF(A41="","",XLOOKUP(A41,Sheet7!B:B,Sheet7!R:T)) -> #REF! | P41: 46071 | Q41: 4 Boxes | R41: UPS | S41: UPS | T41: - | U41: 08067,NJ US | Y41: 46072 | Z41: 46073 | AA41: 46073
A42: 125 -17478952 | B42: X000685781 | C42: 150.3 | E42: Dee Dee Export | F42: Amazon | G42: DDP | I42: WC | K42: =IF(A42="","",XLOOKUP(A42,Sheet7!B:B,Sheet7!K:K)) -> #REF! | L42: =IF(A42="","",XLOOKUP(A42,Sheet7!B:B,Sheet7!R:T)) -> #REF! | P42: 46071 | Q42: 19 Boxes | R42: UPS | S42: UPS | T42: - | U42: 33032,FL US | V42: $189 | Y42: 46072 | Z42: 46077 | AA42: 46077
A43: 125 -17478952 | B43: X000685880 | C43: 200.65 | E43: Thakur Export | F43: THAKUR EXPORTS | G43: DDP | I43: WC | K43: =IF(A43="","",XLOOKUP(A43,Sheet7!B:B,Sheet7!K:K)) -> #REF! | L43: =IF(A43="","",XLOOKUP(A43,Sheet7!B:B,Sheet7!R:T)) -> #REF! | P43: 46071 | Q43: 31 Boxes | R43: UPS | S43: UPS | T43: - | U43: 95991,CA US | V43: $315 | Y43: 46072 | Z43: 46079 | AA43: 46079
A44: 125 -17478952 | B44: X000688655 | C44: 102.35 | E44: Traditional Jaipur | F44: Amazon | G44: DDP | I44: WC | K44: =IF(A44="","",XLOOKUP(A44,Sheet7!B:B,Sheet7!K:K)) -> #REF! | L44: =IF(A44="","",XLOOKUP(A44,Sheet7!B:B,Sheet7!R:T)) -> #REF! | P44: 46071 | Q44: 5 Boxes | R44: UPS | S44: UPS | T44: - | U44: 32206,FL US | V44: $105 | Y44: 46072
A45: 125 -17478952 | B45: X000688706 | C45: 291.5 | E45: ROYAL ARTISANS | F45: Amazon | G45: DDP | I45: WC | K45: =IF(A45="","",XLOOKUP(A45,Sheet7!B:B,Sheet7!K:K)) -> #REF! | L45: =IF(A45="","",XLOOKUP(A45,Sheet7!B:B,Sheet7!R:T)) -> #REF! | P45: 46071 | Q45: 19 Boxes | R45: LTL | S45: AF | T45: Amazon | U45: 18447,PA US | V45: $221 | W45: $120.58 | X45: 1074712389 | Y45: 46072 | Z45: 46077 | AA45: 46078
A46: 125 -17478952 | B46: X000687944 | C46: 80 | E46: Zenith | F46: Amazon | G46: DDP | I46: Regal | K46: =IF(A46="","",XLOOKUP(A46,Sheet7!B:B,Sheet7!K:K)) -> #REF! | L46: =IF(A46="","",XLOOKUP(A46,Sheet7!B:B,Sheet7!R:T)) -> #REF! | P46: 46071 | Q46: 7 Boxes | R46: UPS | S46: UPS | T46: - | U46: 34986 ,FL US | Y46: 46072
A47: 125 -17478952 | B47: X000693350 | C47: 705 | E47: RV INTERNATIONAL | F47: Amazon | G47: DDP | I47: Regal | K47: =IF(A47="","",XLOOKUP(A47,Sheet7!B:B,Sheet7!K:K)) -> #REF! | L47: =IF(A47="","",XLOOKUP(A47,Sheet7!B:B,Sheet7!R:T)) -> #REF! | P47: 46071 | Q47: 47 Boxes | R47: LTL | S47: Central Transport | T47: Trojan Horse | U47: 29330,SC US | V47: $424 | W47: $600 | X47: 416465623 | Y47: 46073 | Z47: 46078
...
